<?xml version="1.0"?>
<robot name="cleaning_robot">
  <!-- Base Link -->
  <link name="base_link">
    <visual>
      <geometry>
        <box size="0.6 0.4 0.2"/>
      </geometry>
      <material name="white"/>
    </visual>
    <collision>
      <geometry>
        <box size="0.6 0.4 0.2"/>
      </geometry>
    </collision>
    <inertial>
      <mass value="15.0"/>
      <inertia ixx="0.1" ixy="0" ixz="0" iyy="0.1" iyz="0" izz="0.1"/>
    </inertial>
  </link>

  <!-- Differential Drive Wheels -->
  <!-- Left Wheel -->
  <link name="left_wheel">
    <visual>
      <geometry>
        <cylinder radius="0.1" length="0.05"/>
      </geometry>
    </visual>
    <collision>
      <geometry>
        <cylinder radius="0.1" length="0.05"/>
      </geometry>
    </collision>
    <inertial>
      <mass value="1.0"/>
      <inertia ixx="0.01" ixy="0" ixz="0" iyy="0.01" iyz="0" izz="0.01"/>
    </inertial>
  </link>

  <!-- Right Wheel -->
  <link name="right_wheel">
    <visual>
      <geometry>
        <cylinder radius="0.1" length="0.05"/>
      </geometry>
    </visual>
    <collision>
      <geometry>
        <cylinder radius="0.1" length="0.05"/>
      </geometry>
    </collision>
    <inertial>
      <mass value="1.0"/>
      <inertia ixx="0.01" ixy="0" ixz="0" iyy="0.01" iyz="0" izz="0.01"/>
    </inertial>
  </link>

  <!-- Joints -->
  <joint name="left_wheel_joint" type="continuous">
    <parent link="base_link"/>
    <child link="left_wheel"/>
    <origin xyz="0 0.25 0" rpy="0 0 0"/>
    <axis xyz="0 1 0"/>
  </joint>

  <joint name="right_wheel_joint" type="continuous">
    <parent link="base_link"/>
    <child link="right_wheel"/>
    <origin xyz="0 -0.25 0" rpy="0 0 0"/>
    <axis xyz="0 1 0"/>
  </joint>

  <!-- Gazebo Plugins for Differential Drive -->
  <gazebo>
    <plugin name="differential_drive_controller" filename="libgazebo_ros_diff_drive.so">
      <legacyMode>true</legacyMode>
      <alwaysOn>true</alwaysOn>
      <updateRate>100</updateRate>
      <leftJoint>left_wheel_joint</leftJoint>
      <rightJoint>right_wheel_joint</rightJoint>
      <wheelSeparation>0.5</wheelSeparation>
      <wheelDiameter>0.2</wheelDiameter>
      <torque>15</torque>
      <commandTopic>/cmd_vel</commandTopic>
      <odometryTopic>/odom</odometryTopic>
      <odometryFrame>odom</odometryFrame>
      <robotBaseFrame>base_link</robotBaseFrame>
    </plugin>
  </gazebo>
</robot>


